Workbook

Sheet Individual stocks
A1: AAPL | J1: AAPL | P1: S&P
A2: Date | B2: Open | C2: High | D2: Low | E2: Close | F2: Adj Close | G2: Volume | H2: Return | J2: Average Total | K2: =AVERAGE(H4:H16) -> 0.00053849966 | P2: Date | Q2: Open | R2: High | S2: Low | T2: Close | U2: Adj Close | V2: Volume | W2: Return
A3: 45965 | B3: 268.33 | C3: 271.49 | D3: 267.62 | E3: 270.04 | F3: 269.78 | G3: 49274800 | J3: Standard Deviation | K3: =_xlfn.STDEV.S(H4:H16) -> 0.010674014 | P3: 45965 | Q3: 6788.52 | R3: 6820.21 | S3: 6766.71 | T3: 6771.55 | U3: 6771.55 | V3: 5739510000
A4: 45966 | B4: 268.61 | C4: 271.7 | D4: 266.93 | E4: 270.14 | F4: 269.88 | G4: 43683100 | H4: =(F4-F3)/F3 -> 0.0003706724 | J4: Covariance | K4: =_xlfn.COVARIANCE.S(H4:H16,$W$4:$W$16) -> 5.6432776e-05 | P4: 45966 | Q4: 6769.77 | R4: 6829.78 | S4: 6763.11 | T4: 6796.29 | U4: 6796.29 | V4: 5939600000 | W4: =(U4-U3)/U3 -> 0.003653521
A5: 45967 | B5: 267.89 | C5: 273.4 | D5: 267.89 | E5: 269.77 | F5: 269.51 | G5: 51204000 | H5: =(F5-F4)/F4 -> -0.0013709797 | J5: Variance | K5: =_xlfn.VAR.S(H4:H16) -> 0.00011393457 | P5: 45967 | Q5: 6787.59 | R5: 6796.68 | S5: 6707.51 | T5: 6720.32 | U5: 6720.32 | V5: 6051900000 | W5: =(U5-U4)/U4 -> -0.011178157
A6: 45968 | B6: 269.8 | C6: 272.29 | D6: 266.77 | E6: 268.47 | F6: 268.21 | G6: 48227400 | H6: =(F6-F5)/F5 -> -0.0048235687 | J6: Beta | K6: =K4/_xlfn.VAR.S(Return!E31:E43) -> 0.60758846 | P6: 45968 | Q6: 6696.18 | R6: 6730.11 | S6: 6631.44 | T6: 6728.8 | U6: 6728.8 | V6: 5926070000 | W6: =(U6-U5)/U5 -> 0.0012618447
A7: 45971 | B7: 268.96 | C7: 273.73 | D7: 267.46 | E7: 269.43 | F7: 269.43 | G7: 41312400 | H7: =(F7-F6)/F6 -> 0.0045486745 | J7: Jensen Alpha | K7: =K2-(0.0002+K6*(AVERAGE($W$4:$W$16)-0.0002)) -> 0.0016109146 | P7: 45971 | Q7: 6785.36 | R7: 6841.32 | S7: 6770.56 | T7: 6832.43 | U7: 6832.43 | V7: 5366050000 | W7: =(U7-U6)/U6 -> 0.015400963
A8: 45972 | B8: 269.81 | C8: 275.91 | D8: 269.8 | E8: 275.25 | F8: 275.25 | G8: 46208300 | H8: =(F8-F7)/F7 -> 0.021601158 | J8: Treynor ratio | K8: =(K2-0.0002)/K6 -> 0.00055711996 | P8: 45972 | Q8: 6815.64 | R8: 6855.13 | S8: 6806.87 | T8: 6846.61 | U8: 6846.61 | V8: 4983490000 | W8: =(U8-U7)/U7 -> 0.0020753963
A9: 45973 | B9: 275 | C9: 275.73 | D9: 271.7 | E9: 273.47 | F9: 273.47 | G9: 48398000 | H9: =(F9-F8)/F8 -> -0.0064668483 | J9: Sharpe ratio | K9: =(K2-0.0002)/K3 -> 0.031712499 | P9: 45973 | Q9: 6867.77 | R9: 6869.91 | S9: 6829.62 | T9: 6850.92 | U9: 6850.92 | V9: 5293610000 | W9: =(U9-U8)/U8 -> 0.00062950862
A10: 45974 | B10: 274.11 | C10: 276.7 | D10: 272.09 | E10: 272.95 | F10: 272.95 | G10: 49602800 | H10: =(F10-F9)/F9 -> -0.0019014883 | P10: 45974 | Q10: 6826.47 | R10: 6828.05 | S10: 6724.72 | T10: 6737.49 | U10: 6737.49 | V10: 5473720000 | W10: =(U10-U9)/U9 -> -0.0165569
A11: 45975 | B11: 271.05 | C11: 275.96 | D11: 269.6 | E11: 272.41 | F11: 272.41 | G11: 47431300 | H11: =(F11-F10)/F10 -> -0.0019783843 | P11: 45975 | Q11: 6672.14 | R11: 6774.31 | S11: 6646.87 | T11: 6734.11 | U11: 6734.11 | V11: 5042660000 | W11: =(U11-U10)/U10 -> -0.0005016705
A12: 45978 | B12: 268.82 | C12: 270.49 | D12: 265.73 | E12: 267.46 | F12: 267.46 | G12: 45018300 | H12: =(F12-F11)/F11 -> -0.018171139 | P12: 45978 | Q12: 6713.61 | R12: 6754.5 | S12: 6638.9 | T12: 6672.41 | U12: 6672.41 | V12: 5204220000 | W12: =(U12-U11)/U11 -> -0.0091623095
A13: 45979 | B13: 269.99 | C13: 270.71 | D13: 265.32 | E13: 267.44 | F13: 267.44 | G13: 45677300 | H13: =(F13-F12)/F12 -> -7.4777537e-05 | P13: 45979 | Q13: 6641.19 | R13: 6666.63 | S13: 6574.32 | T13: 6617.32 | U13: 6617.32 | V13: 5159390000 | W13: =(U13-U12)/U12 -> -0.0082563871
A14: 45980 | B14: 265.53 | C14: 272.21 | D14: 265.5 | E14: 268.56 | F14: 268.56 | G14: 40424500 | H14: =(F14-F13)/F13 -> 0.0041878552 | P14: 45980 | Q14: 6625.84 | R14: 6689.75 | S14: 6603.5 | T14: 6642.16 | U14: 6642.16 | V14: 5021610000 | W14: =(U14-U13)/U13 -> 0.0037537855
A15: 45981 | B15: 270.83 | C15: 275.43 | D15: 265.92 | E15: 266.25 | F15: 266.25 | G15: 45823600 | H15: =(F15-F14)/F14 -> -0.0086014298 | P15: 45981 | Q15: 6737.93 | R15: 6770.35 | S15: 6534.05 | T15: 6538.76 | U15: 6538.76 | V15: 5596080000 | W15: =(U15-U14)/U14 -> -0.015567225
A16: 45982 | B16: 265.95 | C16: 273.33 | D16: 265.67 | E16: 271.49 | F16: 271.49 | G16: 59030800 | H16: =(F16-F15)/F15 -> 0.019680751 | P16: 45982 | Q16: 6555.77 | R16: 6660.05 | S16: 6521.92 | T16: 6602.99 | U16: 6602.99 | V16: 5929930000 | W16: =(U16-U15)/U15 -> 0.0098229634
A19: AMZ | J19: AMZN
A20: Date | B20: Open | C20: High | D20: Low | E20: Close | F20: Adj Close | G20: Volume | H20: Return | J20: Total | K20: =AVERAGE(H22:H24) -> -0.0026481889
A21: 45979 | B21: 228.1 | C21: 230.2 | D21: 222.42 | E21: 222.55 | F21: 222.55 | G21: 60608400 | J21: Standard Deviation | K21: =STDEV(H22:H24) -> 0.020829984
A22: 45980 | B22: 223.74 | C22: 223.74 | D22: 218.52 | E22: 222.69 | F22: 222.69 | G22: 58335600 | H22: =(F22-F21)/F21 -> 0.00062907212 | J22: Covariance | K22: =_xlfn.COVARIANCE.S(H22:H24,W14:W16) -> 0.00027282982
A23: 45981 | B23: 227.05 | C23: 227.41 | D23: 216.74 | E23: 217.14 | F23: 217.14 | G23: 50309000 | H23: =(F23-F22)/F22 -> -0.024922538 | J23: Variance | K23: =_xlfn.VAR.S(H22:H24) -> 0.00043388822
A24: 45982 | B24: 216.35 | C24: 222.21 | D24: 215.18 | E24: 220.69 | F24: 220.69 | G24: 68490500 | H24: =(F24-F23)/F23 -> 0.016348899 | J24: Beta | K24: =K22/_xlfn.VAR.S(Return!E41:E43) -> 1.5519359
J25: Jensen Alpha | K25: =K20-(0.0002+K24*(AVERAGE(W4:W16)-0.0002)) -> 0.00040188333
J26: Treynor ratio | K26: =(K20-0.0002)/K24 -> -0.0018352491
J27: Sharpe ratio | K27: =(K20-0.002)/K21 -> -0.22314895
A30: IWM | J30: IWM
A31: Date | B31: Open | C31: High | D31: Low | E31: Close | F31: Adj Close | G31: Volume | H31: Return | J31: Total | K31: =AVERAGE(H33:H45) -> -0.0016910386
A32: 45965 | B32: 241.79 | C32: 244.06 | D32: 241 | E32: 241.2 | F32: 241.2 | G32: 34468700 | J32: Standard Deviation | K32: =STDEV(H33:H45) -> 0.015724118
A33: 45966 | B33: 241.96 | C33: 245.73 | D33: 241.64 | E33: 244.68 | F33: 244.68 | G33: 38229200 | H33: =(F33-F32)/F32 -> 0.014427861 | J33: Covariance | K33: =_xlfn.COVARIANCE.S(H33:H45,$W$4:$W$16) -> 0.00012972223
A34: 45967 | B34: 244.26 | C34: 244.79 | D34: 240 | E34: 240.35 | F34: 240.35 | G34: 40601200 | H34: =(F34-F33)/F33 -> -0.017696583 | J34: Variance | K34: =_xlfn.VAR.S(H33:H45) -> 0.00024724789
A35: 45968 | B35: 238.41 | C35: 241.66 | D35: 236.27 | E35: 241.61 | F35: 241.61 | G35: 54978900 | H35: =(F35-F34)/F34 -> 0.0052423549 | J35: Beta | K35: =K33/_xlfn.VAR.S(Return!E31:E43) -> 1.3966659
A36: 45971 | B36: 245.01 | C36: 245.24 | D36: 242.25 | E36: 244.03 | F36: 244.03 | G36: 31238000 | H36: =(F36-F35)/F35 -> 0.010016142 | J36: Jensen Alpha | K36: =K31-(0.0002+K35*(AVERAGE($W$4:$W$16)-0.0002)) -> 0.0010338663
A37: 45972 | B37: 243.37 | C37: 244.74 | D37: 242.52 | E37: 244.24 | F37: 244.24 | G37: 27357900 | H37: =(F37-F36)/F36 -> 0.00086054993 | J37: Treynor ratio | K37: =(K31-0.0002)/K35 -> -0.0013539664
A38: 45973 | B38: 244.84 | C38: 246.38 | D38: 243.33 | E38: 243.64 | F38: 243.64 | G38: 35543200 | H38: =(F38-F37)/F37 -> -0.0024566001 | J38: Sharpe ratio | K38: =(K31-0.0002)/K32 -> -0.12026357
A39: 45974 | B39: 241.84 | C39: 242.68 | D39: 235.84 | E39: 236.79 | F39: 236.79 | G39: 65710000 | H39: =(F39-F38)/F38 -> -0.028115252
A40: 45975 | B40: 233.34 | C40: 238.73 | D40: 233.27 | E40: 237.48 | F40: 237.48 | G40: 58344400 | H40: =(F40-F39)/F39 -> 0.0029139744
A41: 45978 | B41: 236.46 | C41: 237.84 | D41: 231.76 | E41: 232.76 | F41: 232.76 | G41: 55765900 | H41: =(F41-F40)/F40 -> -0.019875358
A42: 45979 | B42: 231.31 | C42: 235.08 | D42: 230.96 | E42: 233.47 | F42: 233.47 | G42: 63092500 | H42: =(F42-F41)/F41 -> 0.0030503523
A43: 45980 | B43: 233.8 | C43: 236.37 | D43: 232.43 | E43: 233.43 | F43: 233.43 | G43: 57280500 | H43: =(F43-F42)/F42 -> -0.00017132822
A44: 45981 | B44: 237.24 | C44: 239.1 | D44: 228.9 | E44: 229.11 | F44: 229.11 | G44: 95483000 | H44: =(F44-F43)/F43 -> -0.018506619
...

Sheet Risk and Performance
B1: RISK | E1: PERFORMANCE
B2: Variance | C2: Standard Deviation | D2: Beta | E2: Jensen Alpha | F2: Treynor ratio | G2: Sharpe ratio | H2: Weight
A3: AAPL | B3: ='Individual stocks'!K5 -> 0.00011393457 | C3: ='Individual stocks'!K3 -> 0.010674014 | D3: ='Individual stocks'!K6 -> 0.60758846 | E3: ='Individual stocks'!K7 -> 0.0016109146 | F3: ='Individual stocks'!K8 -> 0.00055711996 | G3: ='Individual stocks'!K9 -> 0.031712499 | H3: 0.0296
A4: AMZN | B4: ='Individual stocks'!K23 -> 0.00043388822 | C4: ='Individual stocks'!K21 -> 0.020829984 | D4: ='Individual stocks'!K24 -> 1.5519359 | E4: ='Individual stocks'!K25 -> 0.00040188333 | F4: ='Individual stocks'!K26 -> -0.0018352491 | G4: ='Individual stocks'!K27 -> -0.22314895 | H4: 0.0952
A5: IWM | B5: ='Individual stocks'!K34 -> 0.00024724789 | C5: ='Individual stocks'!K32 -> 0.015724118 | D5: ='Individual stocks'!K35 -> 1.3966659 | E5: ='Individual stocks'!K36 -> 0.0010338663 | F5: ='Individual stocks'!K37 -> -0.0013539664 | G5: ='Individual stocks'!K38 -> -0.12026357 | H5: 0.051
A6: KO | B6: ='Individual stocks'!K52 -> 9.6733667e-05 | C6: ='Individual stocks'!K50 -> 0.0098353275 | D6: ='Individual stocks'!K53 -> 0.40427981 | E6: ='Individual stocks'!K54 -> 0.0040171429 | F6: ='Individual stocks'!K55 -> 0.0079003534 | G6: ='Individual stocks'!K56 -> 0.32474296 | H6: 0.0034
A7: LLY | B7: ='Individual stocks'!K67 -> 0.00018463448 | C7: ='Individual stocks'!K65 -> 0.013588027 | D7: ='Individual stocks'!K68 -> 0.9624002 | E7: ='Individual stocks'!K69 -> 0.01019667 | F7: ='Individual stocks'!K70 -> 0.0097315493 | G7: ='Individual stocks'!K71 -> 0.68925716 | H7: 0.0737
A8: LMT | B8: ='Individual stocks'!K78 -> 0.00019458677 | C8: ='Individual stocks'!K76 -> 0.013949436 | D8: ='Individual stocks'!K79 -> -0.51631813 | E8: ='Individual stocks'!K80 -> -0.005120996 | F8: ='Individual stocks'!K81 -> 0.0078240906 | G8: ='Individual stocks'!K82 -> -0.28959736 | H8: 0.0181
A9: MSFT | B9: ='Individual stocks'!K96 -> 0.00018610979 | C9: ='Individual stocks'!K94 -> 0.013642206 | D9: ='Individual stocks'!K97 -> 0.29556491 | E9: ='Individual stocks'!K98 -> -0.0093728699 | F9: ='Individual stocks'!K99 -> -0.035230188 | G9: ='Individual stocks'!K100 -> -0.76327883 | H9: 0.1259
A10: VOO | B10: ='Individual stocks'!K109 -> 0.00017067882 | C10: ='Individual stocks'!K107 -> 0.01306441 | D10: ='Individual stocks'!K110 -> 0.98523635 | E10: ='Individual stocks'!K111 -> 0.00011994808 | F10: ='Individual stocks'!K112 -> -0.00074174659 | G10: ='Individual stocks'!K113 -> -0.055937902 | H10: 0.6032

Sheet Return
A1: Date | B1: Portfolio Value | C1: Daily portfolio return | D1: Market value | E1: Daily market return
A2: 9/25/2025 | B2: 10000000 | D2: 6604.72
A3: 9/26/2025 | B3: 10000274 | C3: =(B3-B2)/B2 -> 2.7397e-05 | D3: 6643.7 | E3: =(D3-D2)/D2 -> 0.0059018399
A4: 9/29/2025 | B4: 10001096 | C4: =(B4-B3)/B3 -> 8.2194748e-05 | D4: 6661.21 | E4: =(D4-D3)/D3 -> 0.0026355796 | G4: Market
A5: 9/30/2025 | B5: 10001370 | C5: =(B5-B4)/B4 -> 2.7396997e-05 | D5: 6688.46 | E5: =(D5-D4)/D4 -> 0.0040908484 | G5: Total return | H5: =E44 -> -0.00026193389
A6: 45667 | B6: 10001644 | C6: =(B6-B5)/B5 -> 2.7397247e-05 | D6: 6711.2 | E6: =(D6-D5)/D5 -> 0.0033998858 | G6: Mean daily return | H6: =E45 -> 3.0447349e-05
A7: 45698 | B7: 10001918 | C7: =(B7-B6)/B6 -> 2.7397496e-05 | D7: 6715.35 | E7: =(D7-D6)/D6 -> 0.00061836929 | G7: Standard Deviation | H7: =STDEV(E3:E43) -> 0.0086691445
A8: 45726 | B8: 10002192 | C8: =(B8-B7)/B7 -> 2.7397745e-05 | D8: 6715.79 | E8: =(D8-D7)/D7 -> 6.5521529e-05 | G8: Covariance | H8: =_xlfn.COVARIANCE.S(E3:E43,E3:E43) -> 7.5154066e-05
A9: 45818 | B9: 10003014 | C9: =(B9-B8)/B8 -> 8.2193983e-05 | D9: 6740.28 | E9: =(D9-D8)/D8 -> 0.0036466298 | G9: Variance | H9: =_xlfn.VAR.S(E3:E43) -> 7.5154066e-05
A10: 45848 | B10: 10003288 | C10: =(B10-B9)/B9 -> 2.7397742e-05 | D10: 6714.59 | E10: =(D10-D9)/D9 -> -0.0038114144 | G10: Beta | H10: =H8/H9 -> 1
A11: 45879 | B11: 10003562 | C11: =(B11-B10)/B10 -> 2.7396991e-05 | D11: 6753.72 | E11: =(D11-D10)/D10 -> 0.0058276082
A12: 45910 | B12: 10003836 | C12: =(B12-B11)/B11 -> 2.739724e-05 | D12: 6735.11 | E12: =(D12-D11)/D11 -> -0.0027555184 | G12: Portfolio
A13: 45940 | B13: 10004110 | C13: =(B13-B12)/B12 -> 2.7397489e-05 | D13: 6552.51 | E13: =(D13-D12)/D12 -> -0.027111658 | G13: Total return | H13: =C44 -> -0.006829985
A14: 10/13/2025 | B14: 10004933 | C14: =(B14-B13)/B13 -> 8.2194215e-05 | D14: 6654.72 | E14: =(D14-D13)/D13 -> 0.015598603 | G14: Mean daily return | H14: =C45 -> -0.00016562687
A15: 10/14/2025 | B15: 10005207 | C15: =(B15-B14)/B14 -> 2.7397486e-05 | D15: 6644.31 | E15: =(D15-D14)/D14 -> -0.0015643032 | G15: Standard Deviation | H15: =STDEV(C3:C43) -> 0.0017602967
A16: 10/15/2025 | B16: 10005481 | C16: =(B16-B15)/B15 -> 2.7397735e-05 | D16: 6671.06 | E16: =(D16-D15)/D15 -> 0.0040260012 | G16: Covariance | H16: =_xlfn.COVARIANCE.S(C3:C43,E3:E43) -> 8.101117e-06
A17: 10/16/2025 | B17: 10005755 | C17: =(B17-B16)/B16 -> 2.7396984e-05 | D17: 6629.07 | E17: =(D17-D16)/D16 -> -0.006294352 | G17: Variance | H17: =_xlfn.VAR.S(C3:C43) -> 3.0986446e-06
A18: 10/17/2025 | B18: 10006029 | C18: =(B18-B17)/B17 -> 2.7397233e-05 | D18: 6664.01 | E18: =(D18-D17)/D17 -> 0.0052707242 | G18: Beta | H18: =H16/H9 -> 0.10779346
A19: 10/20/2025 | B19: 10006852 | C19: =(B19-B18)/B18 -> 8.2194444e-05 | D19: 6735.13 | E19: =(D19-D18)/D18 -> 0.010672253
A20: 10/21/2025 | B20: 10007126 | C20: =(B20-B19)/B19 -> 2.7397229e-05 | D20: 6735.35 | E20: =(D20-D19)/D19 -> 3.2664551e-05
A21: 10/22/2025 | B21: 10007400 | C21: =(B21-B20)/B20 -> 2.7397477e-05 | D21: 6699.4 | E21: =(D21-D20)/D20 -> -0.0053375103
A22: 10/23/2025 | B22: 10007674 | C22: =(B22-B21)/B21 -> 2.7397726e-05 | D22: 6738.44 | E22: =(D22-D21)/D21 -> 0.0058273875
A23: 10/24/2025 | B23: 10007948 | C23: =(B23-B22)/B22 -> 2.7396975e-05 | D23: 6791.69 | E23: =(D23-D22)/D22 -> 0.0079024225
A24: 10/27/2025 | B24: 10008771 | C24: =(B24-B23)/B23 -> 8.2194669e-05 | D24: 6875.16 | E24: =(D24-D23)/D23 -> 0.012290019
A25: 10/28/2025 | B25: 10009045 | C25: =(B25-B24)/B24 -> 2.739697e-05 | D25: 6890.89 | E25: =(D25-D24)/D24 -> 0.0022879468
A26: 10/29/2025 | B26: 10009319 | C26: =(B26-B25)/B25 -> 2.7397219e-05 | D26: 6890.59 | E26: =(D26-D25)/D25 -> -4.3535741e-05
A27: 10/30/2025 | B27: 10009594 | C27: =(B27-B26)/B26 -> 2.7397467e-05 | D27: 6822.34 | E27: =(D27-D26)/D26 -> -0.0099048122
A28: 10/31/2025 | B28: 10009868 | C28: =(B28-B27)/B27 -> 2.7397716e-05 | D28: 6840.2 | E28: =(D28-D27)/D27 -> 0.0026178701
A29: 45727 | B29: 10010691 | C29: =(B29-B28)/B28 -> 8.2193893e-05 | D29: 6851.97 | E29: =(D29-D28)/D28 -> 0.0017207099
A30: 45758 | B30: 10002836 | C30: =(B30-B29)/B29 -> -0.00078463418 | D30: 6771.55 | E30: =(D30-D29)/D29 -> -0.011736771
A31: 45788 | B31: 10015570 | C31: =(B31-B30)/B30 -> 0.001273028 | D31: 6796.29 | E31: =(D31-D30)/D30 -> 0.003653521
A32: 45819 | B32: 9969652.6 | C32: =(B32-B31)/B31 -> -0.004584573 | D32: 6720.32 | E32: =(D32-D31)/D31 -> -0.011178157
A33: 45849 | B33: 9970086.5 | C33: =(B33-B32)/B32 -> 4.3522078e-05 | D33: 6728.8 | E33: =(D33-D32)/D32 -> 0.0012618447
A34: 45941 | B34: 9981439.8 | C34: =(B34-B33)/B33 -> 0.0011387364 | D34: 6832.43 | E34: =(D34-D33)/D33 -> 0.015400963
A35: 45972 | B35: 9985935.5 | C35: =(B35-B34)/B34 -> 0.00045040897 | D35: 6846.61 | E35: =(D35-D34)/D34 -> 0.0020753963
A36: 46002 | B36: 9983314.2 | C36: =(B36-B35)/B35 -> -0.00026249519 | D36: 6850.92 | E36: =(D36-D35)/D35 -> 0.00062950862
A37: 11/13/2025 | B37: 9958616 | C37: =(B37-B36)/B36 -> -0.002473954 | D37: 6737.49 | E37: =(D37-D36)/D36 -> -0.0165569
A38: 11/14/2025 | B38: 9962797.7 | C38: =(B38-B37)/B37 -> 0.00041991277 | D38: 6734.11 | E38: =(D38-D37)/D37 -> -0.0005016705
A39: 11/17/2025 | B39: 9946234 | C39: =(B39-B38)/B38 -> -0.0016625561 | D39: 6672.41 | E39: =(D39-D38)/D38 -> -0.0091623095
A40: 11/18/2025 | B40: 9943734.9 | C40: =(B40-B39)/B39 -> -0.00025125892 | D40: 6617.32 | E40: =(D40-D39)/D39 -> -0.0082563871
...

Sheet Beta
B2: Weighted-Average Beta
C3: Beta | D3: Weight
B4: AAPL | C4: ='Individual stocks'!K6 -> 0.60758846 | D4: 0.0296
B5: AMZN | C5: ='Individual stocks'!K24 -> 1.5519359 | D5: 0.0952
B6: IWM | C6: ='Individual stocks'!K35 -> 1.3966659 | D6: 0.051
B7: KO | C7: ='Individual stocks'!K53 -> 0.40427981 | D7: 0.0034
B8: LLY | C8: ='Individual stocks'!K68 -> 0.9624002 | D8: 0.0737
B9: LMT | C9: ='Individual stocks'!K79 -> -0.51631813 | D9: 0.0181
B10: MSFT | C10: ='Individual stocks'!K97 -> 0.29556491 | D10: 0.1259
B11: VOO | C11: ='Individual stocks'!K110 -> 0.98523635 | D11: 0.6032
B12: Stocks Beta | C12: =C4*D4+C5*D5+C6*D6+C7*D7+C8*D8+C9*D9+C10*D10+C11*D11 -> 0.93142315 | D12: 0.55
B13: Portfolio Beta | C13: =C12*D12 -> 0.51228273
B16: Performance measure
C17: Portfolio | D17: Market
B18: Jensen Alpha | C18: =(Return!H14-(0.0002+Return!H18*(Return!H5-0.0002))) -> -0.00031583341 | D18: =Return!H6-(0.0002+Return!H10*(Return!H5-0.0002)) -> 0.00029238124
B19: Sharpe Ratio | C19: =(Return!H13-0.0002)/Return!H15 -> -3.9936363 | D19: =(Return!H5-0.0002)/Return!H7 -> -0.05328483
B20: Treynor Ratio | C20: =(Return!H13-0.0002)/Return!H18 -> -0.065217174 | D20: =(Return!H5-0.0002)/Return!H10 -> -0.00046193389

Sheet Prices
A1: Symbol | B1: Description | C1: Quantity | D1: Last Price | E1: Price Paid | F1: Total price | G1: Day Change | H1: Profit/Loss | I1: Market Value | J1: Profit/Loss Percentage | K1: Beginning proportion | L1: Closing proportion | M1: Weight
A2: AAPL | B2: Apple Inc. | C2: 500 | D2: 277.55 | E2: 270.42 | F2: =C2*E2 -> 135210 | G2: 0.58 | H2: 3565 | I2: 138775 | J2: 0.0264 | K2: =C2*E2/$B$13 -> 0.013521 | L2: =I2/$B$12 -> 0.013972935 | M2: 0.0296
A3: AMZN | B3: Amazon.com, Inc | C3: 1995 | D3: 229.16 | E3: 221.88 | F3: =C3*E3 -> 442650.6 | G3: -0.51 | H3: 14523.2 | I3: 457174.2 | J3: 0.0328 | K3: =C3*E3/$B$13 -> 0.04426506 | L3: =I3/$B$12 -> 0.046031817 | M3: 0.0952
A4: IWM | B4: iShares Russell 2000 ETF | C4: 1000 | D4: 247.3 | E4: 240.5 | F4: =C4*E4 -> 240500 | G4: 2.17 | H4: 6797.14 | I4: 247300 | J4: 0.0283 | K4: =C4*E4/$B$13 -> 0.02405 | L4: =I4/$B$12 -> 0.024900067 | M4: 0.051
A5: KO | B5: The Coca-Cola Company | C5: 200 | D5: 72.88 | E5: 70.02 | F5: =C5*E5 -> 14004 | G5: 0.27 | H5: 572 | I5: 14576 | J5: 0.0408 | K5: =C5*E5/$B$13 -> 0.0014004 | L5: =I5/$B$12 -> 0.0014676238 | M5: 0.0034
A6: LLY | B6: Eli Lilly and Company | C6: 347 | D6: 1104.34 | E6: 1032.43 | F6: =C6*E6 -> 358253.21 | G6: -5.6 | H6: 24952.77 | I6: 383205.98 | J6: 0.0697 | K6: =C6*E6/$B$13 -> 0.035825321 | L6: =I6/$B$12 -> 0.038584127 | M6: 0.0737
A7: LMT | B7: Lockheed Martin Corporation | C7: 200 | D7: 454.16 | E7: 483.5 | F7: =C7*E7 -> 96700 | G7: 1.75 | H7: -5868 | I7: 90832 | J7: -0.0607 | K7: =C7*E7/$B$13 -> 0.00967 | L7: =I7/$B$12 -> 0.0091456648 | M7: 0.0181
A8: MSFT | B8: Microsoft Corporation | C8: 1275 | D8: 485.5 | E8: 483.68 | F8: =C8*E8 -> 616692 | G8: 8.51 | H8: 2315.5 | I8: 619012.5 | J8: 0.0038 | K8: =C8*E8/$B$13 -> 0.0616692 | L8: =I8/$B$12 -> 0.062326942 | M8: 0.1259
A9: VOO | B9: Vanguard S&P 500 ETF | C9: 4700 | D9: 624.95 | E9: 607.24 | F9: =C9*E9 -> 2854028 | G9: 4.29 | H9: 83251 | I9: 2937265 | J9: 0.0292 | K9: =C9*E9/$B$13 -> 0.2854028 | L9: =I9/$B$12 -> 0.29574644 | M9: 0.6032
A10: Portfolio | F10: =SUM(F2:F9) -> 4758037.8 | I10: =SUM(I2:I9) -> 4888140.7
A12: Portoflio value | B12: 9931700.2
A13: Beginning value | B13: 10000000
A14: Total return (%) | B14: =(B12-B13)/B13 -> -0.006829985
A17: Total Market Value | B17: =SUM(I2:I9) -> 4888140.7
A18: Total Cost Basis | B18: =SUM(F2:F9) -> 4758037.8
A19: Total Unrealized P/L | B19: =B17-B18 -> 130102.87
A20: Total return (%) | B20: =(B17-B18)/B18 -> 0.027343808
